[ 2023-04-28 17:38:59,113 ] 186 werkzeug - INFO - [31m[1mWARNING: This is a development server. Do not use it in a production deployment. Use a production WSGI server instead.[0m
 * Running on all addresses (0.0.0.0)
 * Running on http://127.0.0.1:5000
 * Running on http://172.16.85.239:5000
[ 2023-04-28 17:38:59,113 ] 186 werkzeug - INFO - [33mPress CTRL+C to quit[0m
[ 2023-04-28 17:39:52,682 ] 186 werkzeug - INFO - 127.0.0.1 - - [28/Apr/2023 17:39:52] "GET / HTTP/1.1" 200 -
[ 2023-04-28 17:39:53,095 ] 186 werkzeug - INFO - 127.0.0.1 - - [28/Apr/2023 17:39:53] "[33mGET /favicon.ico HTTP/1.1[0m" 404 -
[ 2023-04-28 17:40:22,089 ] 186 werkzeug - INFO - 127.0.0.1 - - [28/Apr/2023 17:40:22] "GET / HTTP/1.1" 200 -
[ 2023-04-28 17:40:32,072 ] 186 werkzeug - INFO - 127.0.0.1 - - [28/Apr/2023 17:40:32] "GET /predictdata HTTP/1.1" 200 -
[ 2023-04-28 17:41:10,983 ] 1414 app - ERROR - Exception on /predictdata [POST]
Traceback (most recent call last):
  File "D:\users1\documents\ML_projects\mlproject\src\utils.py", line 68, in load_object
    with open(file_path, "rb") as file_obj:
FileNotFoundError: [Errno 2] No such file or directory: 'artifacts\\preprocessor.pkl'

During handling of the above exception, another exception occurred:

Traceback (most recent call last):
  File "D:\users1\documents\ML_projects\mlproject\src\pipeline\predict_pipeline.py", line 17, in predict
    preprocessor=load_object(file_path=preprocessor_path)
  File "D:\users1\documents\ML_projects\mlproject\src\utils.py", line 72, in load_object
    raise CustomException(e, sys)
src.exception.CustomException: Error occured in python script name [D:\users1\documents\ML_projects\mlproject\src\utils.py] line number [68] error message[[Errno 2] No such file or directory: 'artifacts\\preprocessor.pkl']

During handling of the above exception, another exception occurred:

Traceback (most recent call last):
  File "D:\users1\documents\ML_projects\mlproject\venv\lib\site-packages\flask\app.py", line 2190, in wsgi_app
    response = self.full_dispatch_request()
  File "D:\users1\documents\ML_projects\mlproject\venv\lib\site-packages\flask\app.py", line 1486, in full_dispatch_request
    rv = self.handle_user_exception(e)
  File "D:\users1\documents\ML_projects\mlproject\venv\lib\site-packages\flask\app.py", line 1484, in full_dispatch_request
    rv = self.dispatch_request()
  File "D:\users1\documents\ML_projects\mlproject\venv\lib\site-packages\flask\app.py", line 1469, in dispatch_request
    return self.ensure_sync(self.view_functions[rule.endpoint])(**view_args)
  File "app.py", line 44, in predict_datapoint
    results=predict_pipeline.predict(pred_df) # predict fucntion of PredictPipeline class
  File "D:\users1\documents\ML_projects\mlproject\src\pipeline\predict_pipeline.py", line 23, in predict
    raise CustomException(e,sys)
src.exception.CustomException: Error occured in python script name [D:\users1\documents\ML_projects\mlproject\src\pipeline\predict_pipeline.py] line number [17] error message[Error occured in python script name [D:\users1\documents\ML_projects\mlproject\src\utils.py] line number [68] error message[[Errno 2] No such file or directory: 'artifacts\\preprocessor.pkl']]
[ 2023-04-28 17:41:11,033 ] 186 werkzeug - INFO - 127.0.0.1 - - [28/Apr/2023 17:41:11] "[35m[1mPOST /predictdata HTTP/1.1[0m" 500 -
